Internal Server Error: /accounts/login/
Traceback (most recent call last):
  File "C:\Users\USER\Desktop\DEV\Django\investment\.venv\Lib\site-packages\django\core\handlers\exception.py", line 55, in inner
    response = get_response(request)
  File "C:\Users\USER\Desktop\DEV\Django\investment\.venv\Lib\site-packages\django\core\handlers\base.py", line 220, in _get_response
    response = response.render()
  File "C:\Users\USER\Desktop\DEV\Django\investment\.venv\Lib\site-packages\django\template\response.py", line 114, in render
    self.content = self.rendered_content
                   ^^^^^^^^^^^^^^^^^^^^^
  File "C:\Users\USER\Desktop\DEV\Django\investment\.venv\Lib\site-packages\django\template\response.py", line 90, in rendered_content
    template = self.resolve_template(self.template_name)
  File "C:\Users\USER\Desktop\DEV\Django\investment\.venv\Lib\site-packages\django\template\response.py", line 72, in resolve_template
    return select_template(template, using=self.using)
  File "C:\Users\USER\Desktop\DEV\Django\investment\.venv\Lib\site-packages\django\template\loader.py", line 47, in select_template
    raise TemplateDoesNotExist(", ".join(template_name_list), chain=chain)
django.template.exceptions.TemplateDoesNotExist: login.html
"GET /accounts/login/?next=/dashboard/ HTTP/1.1" 500 82278
Internal Server Error: /dashboard/
Traceback (most recent call last):
  File "C:\Users\USER\Desktop\DEV\Django\investment\.venv\Lib\site-packages\django\core\handlers\exception.py", line 55, in inner
    response = get_response(request)
  File "C:\Users\USER\Desktop\DEV\Django\investment\.venv\Lib\site-packages\django\core\handlers\base.py", line 197, in _get_response
    response = wrapped_callback(request, *callback_args, **callback_kwargs)
  File "C:\Users\USER\Desktop\DEV\Django\investment\.venv\Lib\site-packages\django\contrib\auth\decorators.py", line 60, in _view_wrapper
    return view_func(request, *args, **kwargs)
  File "C:\Users\USER\Desktop\DEV\Django\investment\core\views.py", line 20, in dashboard
    user_balance = UserBalance.objects.get(user=request.user)
  File "C:\Users\USER\Desktop\DEV\Django\investment\.venv\Lib\site-packages\django\db\models\manager.py", line 87, in manager_method
    return getattr(self.get_queryset(), name)(*args, **kwargs)
           ~~~~~~~~~~~~~~~~~~~~~~~~~~~~~~~~~~^^^^^^^^^^^^^^^^^
  File "C:\Users\USER\Desktop\DEV\Django\investment\.venv\Lib\site-packages\django\db\models\query.py", line 649, in get
    raise self.model.DoesNotExist(
        "%s matching query does not exist." % self.model._meta.object_name
    )
core.models.UserBalance.DoesNotExist: UserBalance matching query does not exist.
"GET /dashboard/ HTTP/1.1" 500 81100
Internal Server Error: /dashboard/
Traceback (most recent call last):
  File "C:\Users\USER\Desktop\DEV\Django\investment\.venv\Lib\site-packages\django\core\handlers\exception.py", line 55, in inner
    response = get_response(request)
  File "C:\Users\USER\Desktop\DEV\Django\investment\.venv\Lib\site-packages\django\core\handlers\base.py", line 197, in _get_response
    response = wrapped_callback(request, *callback_args, **callback_kwargs)
  File "C:\Users\USER\Desktop\DEV\Django\investment\.venv\Lib\site-packages\django\contrib\auth\decorators.py", line 60, in _view_wrapper
    return view_func(request, *args, **kwargs)
  File "C:\Users\USER\Desktop\DEV\Django\investment\core\views.py", line 56, in dashboard
    user_balance = UserBalance.objects.get(user=request.user)
  File "C:\Users\USER\Desktop\DEV\Django\investment\.venv\Lib\site-packages\django\db\models\manager.py", line 87, in manager_method
    return getattr(self.get_queryset(), name)(*args, **kwargs)
           ~~~~~~~~~~~~~~~~~~~~~~~~~~~~~~~~~~^^^^^^^^^^^^^^^^^
  File "C:\Users\USER\Desktop\DEV\Django\investment\.venv\Lib\site-packages\django\db\models\query.py", line 649, in get
    raise self.model.DoesNotExist(
        "%s matching query does not exist." % self.model._meta.object_name
    )
core.models.UserBalance.DoesNotExist: UserBalance matching query does not exist.
"GET /dashboard/ HTTP/1.1" 500 81100
Internal Server Error: /dashboard/
Traceback (most recent call last):
  File "C:\Users\USER\Desktop\DEV\Django\investment\.venv\Lib\site-packages\django\core\handlers\exception.py", line 55, in inner
    response = get_response(request)
  File "C:\Users\USER\Desktop\DEV\Django\investment\.venv\Lib\site-packages\django\core\handlers\base.py", line 197, in _get_response
    response = wrapped_callback(request, *callback_args, **callback_kwargs)
  File "C:\Users\USER\Desktop\DEV\Django\investment\.venv\Lib\site-packages\django\contrib\auth\decorators.py", line 60, in _view_wrapper
    return view_func(request, *args, **kwargs)
  File "C:\Users\USER\Desktop\DEV\Django\investment\core\views.py", line 56, in dashboard
    user_balance = UserBalance.objects.get(user=request.user)
  File "C:\Users\USER\Desktop\DEV\Django\investment\.venv\Lib\site-packages\django\db\models\manager.py", line 87, in manager_method
    return getattr(self.get_queryset(), name)(*args, **kwargs)
           ~~~~~~~~~~~~~~~~~~~~~~~~~~~~~~~~~~^^^^^^^^^^^^^^^^^
  File "C:\Users\USER\Desktop\DEV\Django\investment\.venv\Lib\site-packages\django\db\models\query.py", line 649, in get
    raise self.model.DoesNotExist(
        "%s matching query does not exist." % self.model._meta.object_name
    )
core.models.UserBalance.DoesNotExist: UserBalance matching query does not exist.
"GET /dashboard/ HTTP/1.1" 500 80931
Internal Server Error: /deposit/
Traceback (most recent call last):
  File "C:\Users\USER\Desktop\DEV\Django\investment\.venv\Lib\site-packages\django\core\handlers\exception.py", line 55, in inner
    response = get_response(request)
  File "C:\Users\USER\Desktop\DEV\Django\investment\.venv\Lib\site-packages\django\core\handlers\base.py", line 197, in _get_response
    response = wrapped_callback(request, *callback_args, **callback_kwargs)
  File "C:\Users\USER\Desktop\DEV\Django\investment\.venv\Lib\site-packages\django\contrib\auth\decorators.py", line 60, in _view_wrapper
    return view_func(request, *args, **kwargs)
  File "C:\Users\USER\Desktop\DEV\Django\investment\core\views.py", line 82, in deposit_page
    return render(request, "deposit.html", {"wallets": wallets})
  File "C:\Users\USER\Desktop\DEV\Django\investment\.venv\Lib\site-packages\django\shortcuts.py", line 25, in render
    content = loader.render_to_string(template_name, context, request, using=using)
  File "C:\Users\USER\Desktop\DEV\Django\investment\.venv\Lib\site-packages\django\template\loader.py", line 61, in render_to_string
    template = get_template(template_name, using=using)
  File "C:\Users\USER\Desktop\DEV\Django\investment\.venv\Lib\site-packages\django\template\loader.py", line 19, in get_template
    raise TemplateDoesNotExist(template_name, chain=chain)
django.template.exceptions.TemplateDoesNotExist: deposit.html
"GET /deposit/ HTTP/1.1" 500 87898
Internal Server Error: /invest/
Traceback (most recent call last):
  File "C:\Users\USER\Desktop\DEV\Django\investment\.venv\Lib\site-packages\django\db\backends\utils.py", line 105, in _execute
    return self.cursor.execute(sql, params)
           ~~~~~~~~~~~~~~~~~~~^^^^^^^^^^^^^
  File "C:\Users\USER\Desktop\DEV\Django\investment\.venv\Lib\site-packages\django\db\backends\sqlite3\base.py", line 354, in execute
    return super().execute(query, params)
           ~~~~~~~~~~~~~~~^^^^^^^^^^^^^^^
sqlite3.OperationalError: no such column: core_investmentpackage.description

The above exception was the direct cause of the following exception:

Traceback (most recent call last):
  File "C:\Users\USER\Desktop\DEV\Django\investment\.venv\Lib\site-packages\django\core\handlers\exception.py", line 55, in inner
    response = get_response(request)
  File "C:\Users\USER\Desktop\DEV\Django\investment\.venv\Lib\site-packages\django\core\handlers\base.py", line 197, in _get_response
    response = wrapped_callback(request, *callback_args, **callback_kwargs)
  File "C:\Users\USER\Desktop\DEV\Django\investment\.venv\Lib\site-packages\django\contrib\auth\decorators.py", line 60, in _view_wrapper
    return view_func(request, *args, **kwargs)
  File "C:\Users\USER\Desktop\DEV\Django\investment\core\views.py", line 99, in invest_page
    return render(request, "invest.html", {"packages": packages})
  File "C:\Users\USER\Desktop\DEV\Django\investment\.venv\Lib\site-packages\django\shortcuts.py", line 25, in render
    content = loader.render_to_string(template_name, context, request, using=using)
  File "C:\Users\USER\Desktop\DEV\Django\investment\.venv\Lib\site-packages\django\template\loader.py", line 62, in render_to_string
    return template.render(context, request)
           ~~~~~~~~~~~~~~~^^^^^^^^^^^^^^^^^^
  File "C:\Users\USER\Desktop\DEV\Django\investment\.venv\Lib\site-packages\django\template\backends\django.py", line 107, in render
    return self.template.render(context)
           ~~~~~~~~~~~~~~~~~~~~^^^^^^^^^
  File "C:\Users\USER\Desktop\DEV\Django\investment\.venv\Lib\site-packages\django\template\base.py", line 171, in render
    return self._render(context)
           ~~~~~~~~~~~~^^^^^^^^^
  File "C:\Users\USER\Desktop\DEV\Django\investment\.venv\Lib\site-packages\django\template\base.py", line 163, in _render
    return self.nodelist.render(context)
           ~~~~~~~~~~~~~~~~~~~~^^^^^^^^^
  File "C:\Users\USER\Desktop\DEV\Django\investment\.venv\Lib\site-packages\django\template\base.py", line 1008, in render
    return SafeString("".join([node.render_annotated(context) for node in self]))
                               ~~~~~~~~~~~~~~~~~~~~~^^^^^^^^^
  File "C:\Users\USER\Desktop\DEV\Django\investment\.venv\Lib\site-packages\django\template\base.py", line 969, in render_annotated
    return self.render(context)
           ~~~~~~~~~~~^^^^^^^^^
  File "C:\Users\USER\Desktop\DEV\Django\investment\.venv\Lib\site-packages\django\template\defaulttags.py", line 199, in render
    len_values = len(values)
  File "C:\Users\USER\Desktop\DEV\Django\investment\.venv\Lib\site-packages\django\db\models\query.py", line 382, in __len__
    self._fetch_all()
    ~~~~~~~~~~~~~~~^^
  File "C:\Users\USER\Desktop\DEV\Django\investment\.venv\Lib\site-packages\django\db\models\query.py", line 1928, in _fetch_all
    self._result_cache = list(self._iterable_class(self))
                         ~~~~^^^^^^^^^^^^^^^^^^^^^^^^^^^^
  File "C:\Users\USER\Desktop\DEV\Django\investment\.venv\Lib\site-packages\django\db\models\query.py", line 91, in __iter__
    results = compiler.execute_sql(
        chunked_fetch=self.chunked_fetch, chunk_size=self.chunk_size
    )
  File "C:\Users\USER\Desktop\DEV\Django\investment\.venv\Lib\site-packages\django\db\models\sql\compiler.py", line 1574, in execute_sql
    cursor.execute(sql, params)
    ~~~~~~~~~~~~~~^^^^^^^^^^^^^
  File "C:\Users\USER\Desktop\DEV\Django\investment\.venv\Lib\site-packages\django\db\backends\utils.py", line 122, in execute
    return super().execute(sql, params)
           ~~~~~~~~~~~~~~~^^^^^^^^^^^^^
  File "C:\Users\USER\Desktop\DEV\Django\investment\.venv\Lib\site-packages\django\db\backends\utils.py", line 79, in execute
    return self._execute_with_wrappers(
           ~~~~~~~~~~~~~~~~~~~~~~~~~~~^
        sql, params, many=False, executor=self._execute
        ^^^^^^^^^^^^^^^^^^^^^^^^^^^^^^^^^^^^^^^^^^^^^^^
    )
    ^
  File "C:\Users\USER\Desktop\DEV\Django\investment\.venv\Lib\site-packages\django\db\backends\utils.py", line 92, in _execute_with_wrappers
    return executor(sql, params, many, context)
  File "C:\Users\USER\Desktop\DEV\Django\investment\.venv\Lib\site-packages\django\db\backends\utils.py", line 100, in _execute
    with self.db.wrap_database_errors:
         ^^^^^^^^^^^^^^^^^^^^^^^^^^^^
  File "C:\Users\USER\Desktop\DEV\Django\investment\.venv\Lib\site-packages\django\db\utils.py", line 91, in __exit__
    raise dj_exc_value.with_traceback(traceback) from exc_value
  File "C:\Users\USER\Desktop\DEV\Django\investment\.venv\Lib\site-packages\django\db\backends\utils.py", line 105, in _execute
    return self.cursor.execute(sql, params)
           ~~~~~~~~~~~~~~~~~~~^^^^^^^^^^^^^
  File "C:\Users\USER\Desktop\DEV\Django\investment\.venv\Lib\site-packages\django\db\backends\sqlite3\base.py", line 354, in execute
    return super().execute(query, params)
           ~~~~~~~~~~~~~~~^^^^^^^^^^^^^^^
django.db.utils.OperationalError: no such column: core_investmentpackage.description
"GET /invest/ HTTP/1.1" 500 178055
Internal Server Error: /
Traceback (most recent call last):
  File "C:\Users\USER\Desktop\DEV\Django\investment\.venv\Lib\site-packages\django\core\handlers\exception.py", line 55, in inner
    response = get_response(request)
  File "C:\Users\USER\Desktop\DEV\Django\investment\.venv\Lib\site-packages\django\core\handlers\base.py", line 220, in _get_response
    response = response.render()
  File "C:\Users\USER\Desktop\DEV\Django\investment\.venv\Lib\site-packages\django\template\response.py", line 114, in render
    self.content = self.rendered_content
                   ^^^^^^^^^^^^^^^^^^^^^
  File "C:\Users\USER\Desktop\DEV\Django\investment\.venv\Lib\site-packages\django\template\response.py", line 92, in rendered_content
    return template.render(context, self._request)
           ~~~~~~~~~~~~~~~^^^^^^^^^^^^^^^^^^^^^^^^
  File "C:\Users\USER\Desktop\DEV\Django\investment\.venv\Lib\site-packages\django\template\backends\django.py", line 107, in render
    return self.template.render(context)
           ~~~~~~~~~~~~~~~~~~~~^^^^^^^^^
  File "C:\Users\USER\Desktop\DEV\Django\investment\.venv\Lib\site-packages\django\template\base.py", line 171, in render
    return self._render(context)
           ~~~~~~~~~~~~^^^^^^^^^
  File "C:\Users\USER\Desktop\DEV\Django\investment\.venv\Lib\site-packages\django\template\base.py", line 163, in _render
    return self.nodelist.render(context)
           ~~~~~~~~~~~~~~~~~~~~^^^^^^^^^
  File "C:\Users\USER\Desktop\DEV\Django\investment\.venv\Lib\site-packages\django\template\base.py", line 1008, in render
    return SafeString("".join([node.render_annotated(context) for node in self]))
                               ~~~~~~~~~~~~~~~~~~~~~^^^^^^^^^
  File "C:\Users\USER\Desktop\DEV\Django\investment\.venv\Lib\site-packages\django\template\base.py", line 969, in render_annotated
    return self.render(context)
           ~~~~~~~~~~~^^^^^^^^^
  File "C:\Users\USER\Desktop\DEV\Django\investment\.venv\Lib\site-packages\django\template\defaulttags.py", line 480, in render
    url = reverse(view_name, args=args, kwargs=kwargs, current_app=current_app)
  File "C:\Users\USER\Desktop\DEV\Django\investment\.venv\Lib\site-packages\django\urls\base.py", line 88, in reverse
    return resolver._reverse_with_prefix(view, prefix, *args, **kwargs)
           ~~~~~~~~~~~~~~~~~~~~~~~~~~~~~^^^^^^^^^^^^^^^^^^^^^^^^^^^^^^^
  File "C:\Users\USER\Desktop\DEV\Django\investment\.venv\Lib\site-packages\django\urls\resolvers.py", line 831, in _reverse_with_prefix
    raise NoReverseMatch(msg)
django.urls.exceptions.NoReverseMatch: Reverse for 'password_reset' not found. 'password_reset' is not a valid view function or pattern name.
"GET / HTTP/1.1" 500 114907
Internal Server Error: /invest/
Traceback (most recent call last):
  File "C:\Users\USER\Desktop\DEV\Django\investment\.venv\Lib\site-packages\django\core\handlers\exception.py", line 55, in inner
    response = get_response(request)
  File "C:\Users\USER\Desktop\DEV\Django\investment\.venv\Lib\site-packages\django\core\handlers\base.py", line 197, in _get_response
    response = wrapped_callback(request, *callback_args, **callback_kwargs)
  File "C:\Users\USER\Desktop\DEV\Django\investment\.venv\Lib\site-packages\django\contrib\auth\decorators.py", line 60, in _view_wrapper
    return view_func(request, *args, **kwargs)
  File "C:\Users\USER\Desktop\DEV\Django\investment\core\views.py", line 159, in invest_page
    user_balance.balance -= amount
TypeError: unsupported operand type(s) for -=: 'decimal.Decimal' and 'float'
"POST /invest/ HTTP/1.1" 500 74773
